Workbook

Sheet Сводка
B1: МОИ ПРОДАЖИ — СВОДКА
B2: Всё считается само из листа «Заказы». Заполнять здесь нужно только жёлтые ячейки.
B4: ПРОДАЖИ (выполненные заказы) | E4: ПО МЕСЯЦАМ
B5: Выручка | C5: =SUMIFS(Заказы!$I$4:$I$1003,Заказы!$O$4:$O$1003,"Выполнен") -> 9500 | E5: Год (впишите) | F5: 2026
B6: Чистая прибыль | C6: =SUMIFS(Заказы!$M$4:$M$1003,Заказы!$O$4:$O$1003,"Выполнен") -> 2500 | E6: Месяц | F6: Заказов | G6: Выручка
B7: Маржа | C7: =IF(C5=0,0,C6/C5) -> 0.26315789 | E7: Январь | F7: =COUNTIFS(Заказы!$O$4:$O$1003,"Выполнен",Заказы!$B$4:$B$1003,">="&DATE($F$5,1,1),Заказы!$B$4:$B$1003,"<"&EDATE(DATE($F$5,1,1),1)) -> 0 | G7: =SUMIFS(Заказы!$I$4:$I$1003,Заказы!$O$4:$O$1003,"Выполнен",Заказы!$B$4:$B$1003,">="&DATE($F$5,1,1),Заказы!$B$4:$B$1003,"<"&EDATE(DATE($F$5,1,1),1)) -> 0
B8: Заказов выполнено | C8: =COUNTIFS(Заказы!$O$4:$O$1003,"Выполнен") -> 1 | E8: Февраль | F8: =COUNTIFS(Заказы!$O$4:$O$1003,"Выполнен",Заказы!$B$4:$B$1003,">="&DATE($F$5,2,1),Заказы!$B$4:$B$1003,"<"&EDATE(DATE($F$5,2,1),1)) -> 0 | G8: =SUMIFS(Заказы!$I$4:$I$1003,Заказы!$O$4:$O$1003,"Выполнен",Заказы!$B$4:$B$1003,">="&DATE($F$5,2,1),Заказы!$B$4:$B$1003,"<"&EDATE(DATE($F$5,2,1),1)) -> 0
B9: Продано штук | C9: =SUMIFS(Заказы!$F$4:$F$1003,Заказы!$O$4:$O$1003,"Выполнен") -> 2 | E9: Март | F9: =COUNTIFS(Заказы!$O$4:$O$1003,"Выполнен",Заказы!$B$4:$B$1003,">="&DATE($F$5,3,1),Заказы!$B$4:$B$1003,"<"&EDATE(DATE($F$5,3,1),1)) -> 0 | G9: =SUMIFS(Заказы!$I$4:$I$1003,Заказы!$O$4:$O$1003,"Выполнен",Заказы!$B$4:$B$1003,">="&DATE($F$5,3,1),Заказы!$B$4:$B$1003,"<"&EDATE(DATE($F$5,3,1),1)) -> 0
B10: Средний чек | C10: =IF(C8=0,0,C5/C8) -> 9500 | E10: Апрель | F10: =COUNTIFS(Заказы!$O$4:$O$1003,"Выполнен",Заказы!$B$4:$B$1003,">="&DATE($F$5,4,1),Заказы!$B$4:$B$1003,"<"&EDATE(DATE($F$5,4,1),1)) -> 0 | G10: =SUMIFS(Заказы!$I$4:$I$1003,Заказы!$O$4:$O$1003,"Выполнен",Заказы!$B$4:$B$1003,">="&DATE($F$5,4,1),Заказы!$B$4:$B$1003,"<"&EDATE(DATE($F$5,4,1),1)) -> 0
B11: Скидок дано | C11: =SUMIFS(Заказы!$H$4:$H$1003,Заказы!$O$4:$O$1003,"Выполнен") -> 500 | E11: Май | F11: =COUNTIFS(Заказы!$O$4:$O$1003,"Выполнен",Заказы!$B$4:$B$1003,">="&DATE($F$5,5,1),Заказы!$B$4:$B$1003,"<"&EDATE(DATE($F$5,5,1),1)) -> 0 | G11: =SUMIFS(Заказы!$I$4:$I$1003,Заказы!$O$4:$O$1003,"Выполнен",Заказы!$B$4:$B$1003,">="&DATE($F$5,5,1),Заказы!$B$4:$B$1003,"<"&EDATE(DATE($F$5,5,1),1)) -> 0
B12: Доставка (оплачена клиентами) | C12: =SUMIFS(Заказы!$J$4:$J$1003,Заказы!$O$4:$O$1003,"Выполнен") -> 0 | E12: Июнь | F12: =COUNTIFS(Заказы!$O$4:$O$1003,"Выполнен",Заказы!$B$4:$B$1003,">="&DATE($F$5,6,1),Заказы!$B$4:$B$1003,"<"&EDATE(DATE($F$5,6,1),1)) -> 0 | G12: =SUMIFS(Заказы!$I$4:$I$1003,Заказы!$O$4:$O$1003,"Выполнен",Заказы!$B$4:$B$1003,">="&DATE($F$5,6,1),Заказы!$B$4:$B$1003,"<"&EDATE(DATE($F$5,6,1),1)) -> 0
B13: ОЖИДАЮТ (ещё не закрыты) | E13: Июль | F13: =COUNTIFS(Заказы!$O$4:$O$1003,"Выполнен",Заказы!$B$4:$B$1003,">="&DATE($F$5,7,1),Заказы!$B$4:$B$1003,"<"&EDATE(DATE($F$5,7,1),1)) -> 0 | G13: =SUMIFS(Заказы!$I$4:$I$1003,Заказы!$O$4:$O$1003,"Выполнен",Заказы!$B$4:$B$1003,">="&DATE($F$5,7,1),Заказы!$B$4:$B$1003,"<"&EDATE(DATE($F$5,7,1),1)) -> 0
B14: Ожидает отправки — заказов | C14: =COUNTIFS(Заказы!$O$4:$O$1003,"Ожидает отправки") -> 1 | E14: Август | F14: =COUNTIFS(Заказы!$O$4:$O$1003,"Выполнен",Заказы!$B$4:$B$1003,">="&DATE($F$5,8,1),Заказы!$B$4:$B$1003,"<"&EDATE(DATE($F$5,8,1),1)) -> 0 | G14: =SUMIFS(Заказы!$I$4:$I$1003,Заказы!$O$4:$O$1003,"Выполнен",Заказы!$B$4:$B$1003,">="&DATE($F$5,8,1),Заказы!$B$4:$B$1003,"<"&EDATE(DATE($F$5,8,1),1)) -> 0
B15: Ожидает отправки — к получению | C15: =SUMIFS(Заказы!$K$4:$K$1003,Заказы!$O$4:$O$1003,"Ожидает отправки") -> 2100 | E15: Сентябрь | F15: =COUNTIFS(Заказы!$O$4:$O$1003,"Выполнен",Заказы!$B$4:$B$1003,">="&DATE($F$5,9,1),Заказы!$B$4:$B$1003,"<"&EDATE(DATE($F$5,9,1),1)) -> 0 | G15: =SUMIFS(Заказы!$I$4:$I$1003,Заказы!$O$4:$O$1003,"Выполнен",Заказы!$B$4:$B$1003,">="&DATE($F$5,9,1),Заказы!$B$4:$B$1003,"<"&EDATE(DATE($F$5,9,1),1)) -> 0
B16: Отправлен (в пути) — заказов | C16: =COUNTIFS(Заказы!$O$4:$O$1003,"Отправлен (в пути)") -> 0 | E16: Октябрь | F16: =COUNTIFS(Заказы!$O$4:$O$1003,"Выполнен",Заказы!$B$4:$B$1003,">="&DATE($F$5,10,1),Заказы!$B$4:$B$1003,"<"&EDATE(DATE($F$5,10,1),1)) -> 1 | G16: =SUMIFS(Заказы!$I$4:$I$1003,Заказы!$O$4:$O$1003,"Выполнен",Заказы!$B$4:$B$1003,">="&DATE($F$5,10,1),Заказы!$B$4:$B$1003,"<"&EDATE(DATE($F$5,10,1),1)) -> 9500
B17: Отправлен (в пути) — к получению | C17: =SUMIFS(Заказы!$K$4:$K$1003,Заказы!$O$4:$O$1003,"Отправлен (в пути)") -> 0 | E17: Ноябрь | F17: =COUNTIFS(Заказы!$O$4:$O$1003,"Выполнен",Заказы!$B$4:$B$1003,">="&DATE($F$5,11,1),Заказы!$B$4:$B$1003,"<"&EDATE(DATE($F$5,11,1),1)) -> 0 | G17: =SUMIFS(Заказы!$I$4:$I$1003,Заказы!$O$4:$O$1003,"Выполнен",Заказы!$B$4:$B$1003,">="&DATE($F$5,11,1),Заказы!$B$4:$B$1003,"<"&EDATE(DATE($F$5,11,1),1)) -> 0
B18: Ожидает самовывоза — заказов | C18: =COUNTIFS(Заказы!$O$4:$O$1003,"Ожидает самовывоза") -> 1 | E18: Декабрь | F18: =COUNTIFS(Заказы!$O$4:$O$1003,"Выполнен",Заказы!$B$4:$B$1003,">="&DATE($F$5,12,1),Заказы!$B$4:$B$1003,"<"&EDATE(DATE($F$5,12,1),1)) -> 0 | G18: =SUMIFS(Заказы!$I$4:$I$1003,Заказы!$O$4:$O$1003,"Выполнен",Заказы!$B$4:$B$1003,">="&DATE($F$5,12,1),Заказы!$B$4:$B$1003,"<"&EDATE(DATE($F$5,12,1),1)) -> 0
B19: Ожидает самовывоза — к получению | C19: =SUMIFS(Заказы!$K$4:$K$1003,Заказы!$O$4:$O$1003,"Ожидает самовывоза") -> 11800 | E19: Итого | F19: =SUM(F7:F18) -> 1 | G19: =SUM(G7:G18) -> 9500
B20: ВСЕГО в ожидании | C20: =C15+C17+C19 -> 13900
B21: Ожидаемая прибыль с них | C21: =SUMIFS(Заказы!$M$4:$M$1003,Заказы!$O$4:$O$1003,"Ожидает отправки")+SUMIFS(Заказы!$M$4:$M$1003,Заказы!$O$4:$O$1003,"Отправлен (в пути)")+SUMIFS(Заказы!$M$4:$M$1003,Заказы!$O$4:$O$1003,"Ожидает самовывоза") -> 5200 | E21: СПОСОБ ПОЛУЧЕНИЯ (выполнено)
B22: Не оплачено (по активным заказам) | C22: =SUMIFS(Заказы!$K$4:$K$1003,Заказы!$P$4:$P$1003,"Не оплачен",Заказы!$O$4:$O$1003,"<>Отменён") -> 11800 | E22: Самовывоз | F22: =COUNTIFS(Заказы!$O$4:$O$1003,"Выполнен",Заказы!$N$4:$N$1003,"Самовывоз") -> 1 | G22: =SUMIFS(Заказы!$I$4:$I$1003,Заказы!$O$4:$O$1003,"Выполнен",Заказы!$N$4:$N$1003,"Самовывоз") -> 9500
B23: Отменено заказов | C23: =COUNTIFS(Заказы!$O$4:$O$1003,"Отменён") -> 0 | E23: СДЭК | F23: =COUNTIFS(Заказы!$O$4:$O$1003,"Выполнен",Заказы!$N$4:$N$1003,"СДЭК") -> 0 | G23: =SUMIFS(Заказы!$I$4:$I$1003,Заказы!$O$4:$O$1003,"Выполнен",Заказы!$N$4:$N$1003,"СДЭК") -> 0
E24: Маршрутка | F24: =COUNTIFS(Заказы!$O$4:$O$1003,"Выполнен",Заказы!$N$4:$N$1003,"Маршрутка") -> 0 | G24: =SUMIFS(Заказы!$I$4:$I$1003,Заказы!$O$4:$O$1003,"Выполнен",Заказы!$N$4:$N$1003,"Маршрутка") -> 0
B25: ПЛАН НА МЕСЯЦ | E25: Курьер | F25: =COUNTIFS(Заказы!$O$4:$O$1003,"Выполнен",Заказы!$N$4:$N$1003,"Курьер") -> 0 | G25: =SUMIFS(Заказы!$I$4:$I$1003,Заказы!$O$4:$O$1003,"Выполнен",Заказы!$N$4:$N$1003,"Курьер") -> 0
B26: План продаж на месяц (впишите) | C26: 300000 | E26: Почта | F26: =COUNTIFS(Заказы!$O$4:$O$1003,"Выполнен",Заказы!$N$4:$N$1003,"Почта") -> 0 | G26: =SUMIFS(Заказы!$I$4:$I$1003,Заказы!$O$4:$O$1003,"Выполнен",Заказы!$N$4:$N$1003,"Почта") -> 0
B27: Факт за текущий месяц | C27: =SUMIFS(Заказы!$I$4:$I$1003,Заказы!$O$4:$O$1003,"Выполнен",Заказы!$B$4:$B$1003,">="&DATE(YEAR(TODAY()),MONTH(TODAY()),1),Заказы!$B$4:$B$1003,"<"&EDATE(DATE(YEAR(TODAY()),MONTH(TODAY()),1),1)) -> 9500
B28: Выполнение плана | C28: =IF(C26=0,0,C27/C26) -> 0.031666667
B29: Осталось до плана | C29: =MAX(0,C26-C27) -> 290500
B31: СКЛАД
B32: Позиций закончилось (остаток ≤ 0) | C32: =COUNTIFS(Товары!$B$4:$B$63,"<>",Товары!$I$4:$I$63,"<=0") -> 5
B33: Позиций на исходе (остаток = 1) | C33: =COUNTIFS(Товары!$B$4:$B$63,"<>",Товары!$I$4:$I$63,1) -> 1
B34: Свободный остаток по закупке | C34: =SUMPRODUCT((Товары!$B$4:$B$63<>"")*N(+Товары!$I$4:$I$63),Товары!$C$4:$C$63) -> 200050

Sheet Шаблон заказа
A1: ШАБЛОН ЗАКАЗА — скопируйте, заполните, отправьте Claude
A2: Пустые строки можно не заполнять. Несколько товаров — через запятую.
A4: Заказ: | B4: (дата, если не сегодня)
A5: Клиент:
A6: Телефон:
A7: Товары: | B7: Натурал коллаген 2, Цинк 1
A8: Скидка: | B8: 0
A9: Получение: | B9: Самовывоз / СДЭК / Маршрутка / Курьер / Почта
A10: Доставка ₽: | B10: 0
A11: Адрес / куда: | B11: город, ПВЗ, номер маршрутки
A12: Оплата: | B12: Оплачен / Предоплата / Не оплачен
A13: Статус: | B13: Ожидает отправки / Ожидает самовывоза / Выполнен
A14: Комментарий:
A17: Чтобы обновить уже внесённый заказ, напишите коротко:
A18: «Ахмед забрал» · «Аминат отправили, трек 1234567» · «Ислам отменил»

Sheet Товары
A1: ТОВАРЫ И ОСТАТКИ
A2: Цены и приход — из «Касса BIO lAYT». «Продано ранее» — продажи из кассы до начала учёта в этой таблице. Новый товар — допишите строку внизу.
A3: № | B3: Товар | C3: Опт-цена | D3: Цена продажи | E3: Приход, шт | F3: Продано ранее, шт | G3: Продано (выполнено), шт | H3: В ожидании, шт | I3: Остаток свободный, шт | J3: Выручка (выполнено) | K3: Прибыль (выполнено) | L3: Ожидается выручки | M3: Маржа, % | N3: Комментарий
A4: =IF(B4="","",ROW()-3) -> 1 | B4: Натурал коллаген | C4: 3500 | D4: 5000 | E4: 60 | F4: 33 | G4: =IF(B4="","",SUMIFS(Заказы!$F$4:$F$1003,Заказы!$E$4:$E$1003,B4,Заказы!$O$4:$O$1003,"Выполнен")) -> 2 | H4: =IF(B4="","",SUMIFS(Заказы!$F$4:$F$1003,Заказы!$E$4:$E$1003,B4,Заказы!$O$4:$O$1003,"Ожидает отправки")+SUMIFS(Заказы!$F$4:$F$1003,Заказы!$E$4:$E$1003,B4,Заказы!$O$4:$O$1003,"Отправлен (в пути)")+SUMIFS(Заказы!$F$4:$F$1003,Заказы!$E$4:$E$1003,B4,Заказы!$O$4:$O$1003,"Ожидает самовывоза")) -> 0 | I4: =IF(B4="","",N(E4)-N(F4)-G4-H4) -> 25 | J4: =IF(B4="","",SUMIFS(Заказы!$I$4:$I$1003,Заказы!$E$4:$E$1003,B4,Заказы!$O$4:$O$1003,"Выполнен")) -> 9500 | K4: =IF(B4="","",SUMIFS(Заказы!$M$4:$M$1003,Заказы!$E$4:$E$1003,B4,Заказы!$O$4:$O$1003,"Выполнен")) -> 2500 | L4: =IF(B4="","",SUMIFS(Заказы!$I$4:$I$1003,Заказы!$E$4:$E$1003,B4,Заказы!$O$4:$O$1003,"Ожидает отправки")+SUMIFS(Заказы!$I$4:$I$1003,Заказы!$E$4:$E$1003,B4,Заказы!$O$4:$O$1003,"Отправлен (в пути)")+SUMIFS(Заказы!$I$4:$I$1003,Заказы!$E$4:$E$1003,B4,Заказы!$O$4:$O$1003,"Ожидает самовывоза")) -> 0 | M4: =IF(OR(B4="",N(J4)=0),"",K4/J4) -> 0.26315789
A5: =IF(B5="","",ROW()-3) -> 2 | B5: Морской коллаген | C5: 0 | D5: 0 | E5: 5 | G5: =IF(B5="","",SUMIFS(Заказы!$F$4:$F$1003,Заказы!$E$4:$E$1003,B5,Заказы!$O$4:$O$1003,"Выполнен")) -> 0 | H5: =IF(B5="","",SUMIFS(Заказы!$F$4:$F$1003,Заказы!$E$4:$E$1003,B5,Заказы!$O$4:$O$1003,"Ожидает отправки")+SUMIFS(Заказы!$F$4:$F$1003,Заказы!$E$4:$E$1003,B5,Заказы!$O$4:$O$1003,"Отправлен (в пути)")+SUMIFS(Заказы!$F$4:$F$1003,Заказы!$E$4:$E$1003,B5,Заказы!$O$4:$O$1003,"Ожидает самовывоза")) -> 0 | I5: =IF(B5="","",N(E5)-N(F5)-G5-H5) -> 5 | J5: =IF(B5="","",SUMIFS(Заказы!$I$4:$I$1003,Заказы!$E$4:$E$1003,B5,Заказы!$O$4:$O$1003,"Выполнен")) -> 0 | K5: =IF(B5="","",SUMIFS(Заказы!$M$4:$M$1003,Заказы!$E$4:$E$1003,B5,Заказы!$O$4:$O$1003,"Выполнен")) -> 0 | L5: =IF(B5="","",SUMIFS(Заказы!$I$4:$I$1003,Заказы!$E$4:$E$1003,B5,Заказы!$O$4:$O$1003,"Ожидает отправки")+SUMIFS(Заказы!$I$4:$I$1003,Заказы!$E$4:$E$1003,B5,Заказы!$O$4:$O$1003,"Отправлен (в пути)")+SUMIFS(Заказы!$I$4:$I$1003,Заказы!$E$4:$E$1003,B5,Заказы!$O$4:$O$1003,"Ожидает самовывоза")) -> 0 | M5: =IF(OR(B5="",N(J5)=0),"",K5/J5)
A6: =IF(B6="","",ROW()-3) -> 3 | B6: Магний +В6 | C6: 1000 | D6: 2500 | E6: 5 | F6: 3 | G6: =IF(B6="","",SUMIFS(Заказы!$F$4:$F$1003,Заказы!$E$4:$E$1003,B6,Заказы!$O$4:$O$1003,"Выполнен")) -> 0 | H6: =IF(B6="","",SUMIFS(Заказы!$F$4:$F$1003,Заказы!$E$4:$E$1003,B6,Заказы!$O$4:$O$1003,"Ожидает отправки")+SUMIFS(Заказы!$F$4:$F$1003,Заказы!$E$4:$E$1003,B6,Заказы!$O$4:$O$1003,"Отправлен (в пути)")+SUMIFS(Заказы!$F$4:$F$1003,Заказы!$E$4:$E$1003,B6,Заказы!$O$4:$O$1003,"Ожидает самовывоза")) -> 0 | I6: =IF(B6="","",N(E6)-N(F6)-G6-H6) -> 2 | J6: =IF(B6="","",SUMIFS(Заказы!$I$4:$I$1003,Заказы!$E$4:$E$1003,B6,Заказы!$O$4:$O$1003,"Выполнен")) -> 0 | K6: =IF(B6="","",SUMIFS(Заказы!$M$4:$M$1003,Заказы!$E$4:$E$1003,B6,Заказы!$O$4:$O$1003,"Выполнен")) -> 0 | L6: =IF(B6="","",SUMIFS(Заказы!$I$4:$I$1003,Заказы!$E$4:$E$1003,B6,Заказы!$O$4:$O$1003,"Ожидает отправки")+SUMIFS(Заказы!$I$4:$I$1003,Заказы!$E$4:$E$1003,B6,Заказы!$O$4:$O$1003,"Отправлен (в пути)")+SUMIFS(Заказы!$I$4:$I$1003,Заказы!$E$4:$E$1003,B6,Заказы!$O$4:$O$1003,"Ожидает самовывоза")) -> 0 | M6: =IF(OR(B6="",N(J6)=0),"",K6/J6)
A7: =IF(B7="","",ROW()-3) -> 4 | B7: Цеолит | C7: 1050 | D7: 1800 | E7: 5 | G7: =IF(B7="","",SUMIFS(Заказы!$F$4:$F$1003,Заказы!$E$4:$E$1003,B7,Заказы!$O$4:$O$1003,"Выполнен")) -> 0 | H7: =IF(B7="","",SUMIFS(Заказы!$F$4:$F$1003,Заказы!$E$4:$E$1003,B7,Заказы!$O$4:$O$1003,"Ожидает отправки")+SUMIFS(Заказы!$F$4:$F$1003,Заказы!$E$4:$E$1003,B7,Заказы!$O$4:$O$1003,"Отправлен (в пути)")+SUMIFS(Заказы!$F$4:$F$1003,Заказы!$E$4:$E$1003,B7,Заказы!$O$4:$O$1003,"Ожидает самовывоза")) -> 0 | I7: =IF(B7="","",N(E7)-N(F7)-G7-H7) -> 5 | J7: =IF(B7="","",SUMIFS(Заказы!$I$4:$I$1003,Заказы!$E$4:$E$1003,B7,Заказы!$O$4:$O$1003,"Выполнен")) -> 0 | K7: =IF(B7="","",SUMIFS(Заказы!$M$4:$M$1003,Заказы!$E$4:$E$1003,B7,Заказы!$O$4:$O$1003,"Выполнен")) -> 0 | L7: =IF(B7="","",SUMIFS(Заказы!$I$4:$I$1003,Заказы!$E$4:$E$1003,B7,Заказы!$O$4:$O$1003,"Ожидает отправки")+SUMIFS(Заказы!$I$4:$I$1003,Заказы!$E$4:$E$1003,B7,Заказы!$O$4:$O$1003,"Отправлен (в пути)")+SUMIFS(Заказы!$I$4:$I$1003,Заказы!$E$4:$E$1003,B7,Заказы!$O$4:$O$1003,"Ожидает самовывоза")) -> 0 | M7: =IF(OR(B7="",N(J7)=0),"",K7/J7)
A8: =IF(B8="","",ROW()-3) -> 5 | B8: Коэнзим Q10 | C8: 1400 | D8: 3600 | E8: 5 | G8: =IF(B8="","",SUMIFS(Заказы!$F$4:$F$1003,Заказы!$E$4:$E$1003,B8,Заказы!$O$4:$O$1003,"Выполнен")) -> 0 | H8: =IF(B8="","",SUMIFS(Заказы!$F$4:$F$1003,Заказы!$E$4:$E$1003,B8,Заказы!$O$4:$O$1003,"Ожидает отправки")+SUMIFS(Заказы!$F$4:$F$1003,Заказы!$E$4:$E$1003,B8,Заказы!$O$4:$O$1003,"Отправлен (в пути)")+SUMIFS(Заказы!$F$4:$F$1003,Заказы!$E$4:$E$1003,B8,Заказы!$O$4:$O$1003,"Ожидает самовывоза")) -> 0 | I8: =IF(B8="","",N(E8)-N(F8)-G8-H8) -> 5 | J8: =IF(B8="","",SUMIFS(Заказы!$I$4:$I$1003,Заказы!$E$4:$E$1003,B8,Заказы!$O$4:$O$1003,"Выполнен")) -> 0 | K8: =IF(B8="","",SUMIFS(Заказы!$M$4:$M$1003,Заказы!$E$4:$E$1003,B8,Заказы!$O$4:$O$1003,"Выполнен")) -> 0 | L8: =IF(B8="","",SUMIFS(Заказы!$I$4:$I$1003,Заказы!$E$4:$E$1003,B8,Заказы!$O$4:$O$1003,"Ожидает отправки")+SUMIFS(Заказы!$I$4:$I$1003,Заказы!$E$4:$E$1003,B8,Заказы!$O$4:$O$1003,"Отправлен (в пути)")+SUMIFS(Заказы!$I$4:$I$1003,Заказы!$E$4:$E$1003,B8,Заказы!$O$4:$O$1003,"Ожидает самовывоза")) -> 0 | M8: =IF(OR(B8="",N(J8)=0),"",K8/J8)
A9: =IF(B9="","",ROW()-3) -> 6 | B9: Компл.вит. М | C9: 1300 | D9: 2500 | E9: 15 | F9: 2 | G9: =IF(B9="","",SUMIFS(Заказы!$F$4:$F$1003,Заказы!$E$4:$E$1003,B9,Заказы!$O$4:$O$1003,"Выполнен")) -> 0 | H9: =IF(B9="","",SUMIFS(Заказы!$F$4:$F$1003,Заказы!$E$4:$E$1003,B9,Заказы!$O$4:$O$1003,"Ожидает отправки")+SUMIFS(Заказы!$F$4:$F$1003,Заказы!$E$4:$E$1003,B9,Заказы!$O$4:$O$1003,"Отправлен (в пути)")+SUMIFS(Заказы!$F$4:$F$1003,Заказы!$E$4:$E$1003,B9,Заказы!$O$4:$O$1003,"Ожидает самовывоза")) -> 0 | I9: =IF(B9="","",N(E9)-N(F9)-G9-H9) -> 13 | J9: =IF(B9="","",SUMIFS(Заказы!$I$4:$I$1003,Заказы!$E$4:$E$1003,B9,Заказы!$O$4:$O$1003,"Выполнен")) -> 0 | K9: =IF(B9="","",SUMIFS(Заказы!$M$4:$M$1003,Заказы!$E$4:$E$1003,B9,Заказы!$O$4:$O$1003,"Выполнен")) -> 0 | L9: =IF(B9="","",SUMIFS(Заказы!$I$4:$I$1003,Заказы!$E$4:$E$1003,B9,Заказы!$O$4:$O$1003,"Ожидает отправки")+SUMIFS(Заказы!$I$4:$I$1003,Заказы!$E$4:$E$1003,B9,Заказы!$O$4:$O$1003,"Отправлен (в пути)")+SUMIFS(Заказы!$I$4:$I$1003,Заказы!$E$4:$E$1003,B9,Заказы!$O$4:$O$1003,"Ожидает самовывоза")) -> 0 | M9: =IF(OR(B9="",N(J9)=0),"",K9/J9)
A10: =IF(B10="","",ROW()-3) -> 7 | B10: МSМ | C10: 1000 | D10: 1900 | E10: 5 | F10: 1 | G10: =IF(B10="","",SUMIFS(Заказы!$F$4:$F$1003,Заказы!$E$4:$E$1003,B10,Заказы!$O$4:$O$1003,"Выполнен")) -> 0 | H10: =IF(B10="","",SUMIFS(Заказы!$F$4:$F$1003,Заказы!$E$4:$E$1003,B10,Заказы!$O$4:$O$1003,"Ожидает отправки")+SUMIFS(Заказы!$F$4:$F$1003,Заказы!$E$4:$E$1003,B10,Заказы!$O$4:$O$1003,"Отправлен (в пути)")+SUMIFS(Заказы!$F$4:$F$1003,Заказы!$E$4:$E$1003,B10,Заказы!$O$4:$O$1003,"Ожидает самовывоза")) -> 0 | I10: =IF(B10="","",N(E10)-N(F10)-G10-H10) -> 4 | J10: =IF(B10="","",SUMIFS(Заказы!$I$4:$I$1003,Заказы!$E$4:$E$1003,B10,Заказы!$O$4:$O$1003,"Выполнен")) -> 0 | K10: =IF(B10="","",SUMIFS(Заказы!$M$4:$M$1003,Заказы!$E$4:$E$1003,B10,Заказы!$O$4:$O$1003,"Выполнен")) -> 0 | L10: =IF(B10="","",SUMIFS(Заказы!$I$4:$I$1003,Заказы!$E$4:$E$1003,B10,Заказы!$O$4:$O$1003,"Ожидает отправки")+SUMIFS(Заказы!$I$4:$I$1003,Заказы!$E$4:$E$1003,B10,Заказы!$O$4:$O$1003,"Отправлен (в пути)")+SUMIFS(Заказы!$I$4:$I$1003,Заказы!$E$4:$E$1003,B10,Заказы!$O$4:$O$1003,"Ожидает самовывоза")) -> 0 | M10: =IF(OR(B10="",N(J10)=0),"",K10/J10)
A11: =IF(B11="","",ROW()-3) -> 8 | B11: L-Карнитин | C11: 650 | D11: 1600 | E11: 3 | G11: =IF(B11="","",SUMIFS(Заказы!$F$4:$F$1003,Заказы!$E$4:$E$1003,B11,Заказы!$O$4:$O$1003,"Выполнен")) -> 0 | H11: =IF(B11="","",SUMIFS(Заказы!$F$4:$F$1003,Заказы!$E$4:$E$1003,B11,Заказы!$O$4:$O$1003,"Ожидает отправки")+SUMIFS(Заказы!$F$4:$F$1003,Заказы!$E$4:$E$1003,B11,Заказы!$O$4:$O$1003,"Отправлен (в пути)")+SUMIFS(Заказы!$F$4:$F$1003,Заказы!$E$4:$E$1003,B11,Заказы!$O$4:$O$1003,"Ожидает самовывоза")) -> 0 | I11: =IF(B11="","",N(E11)-N(F11)-G11-H11) -> 3 | J11: =IF(B11="","",SUMIFS(Заказы!$I$4:$I$1003,Заказы!$E$4:$E$1003,B11,Заказы!$O$4:$O$1003,"Выполнен")) -> 0 | K11: =IF(B11="","",SUMIFS(Заказы!$M$4:$M$1003,Заказы!$E$4:$E$1003,B11,Заказы!$O$4:$O$1003,"Выполнен")) -> 0 | L11: =IF(B11="","",SUMIFS(Заказы!$I$4:$I$1003,Заказы!$E$4:$E$1003,B11,Заказы!$O$4:$O$1003,"Ожидает отправки")+SUMIFS(Заказы!$I$4:$I$1003,Заказы!$E$4:$E$1003,B11,Заказы!$O$4:$O$1003,"Отправлен (в пути)")+SUMIFS(Заказы!$I$4:$I$1003,Заказы!$E$4:$E$1003,B11,Заказы!$O$4:$O$1003,"Ожидает самовывоза")) -> 0 | M11: =IF(OR(B11="",N(J11)=0),"",K11/J11)
A12: =IF(B12="","",ROW()-3) -> 9 | B12: L-Аргинин | C12: 1200 | D12: 2900 | E12: 4 | G12: =IF(B12="","",SUMIFS(Заказы!$F$4:$F$1003,Заказы!$E$4:$E$1003,B12,Заказы!$O$4:$O$1003,"Выполнен")) -> 0 | H12: =IF(B12="","",SUMIFS(Заказы!$F$4:$F$1003,Заказы!$E$4:$E$1003,B12,Заказы!$O$4:$O$1003,"Ожидает отправки")+SUMIFS(Заказы!$F$4:$F$1003,Заказы!$E$4:$E$1003,B12,Заказы!$O$4:$O$1003,"Отправлен (в пути)")+SUMIFS(Заказы!$F$4:$F$1003,Заказы!$E$4:$E$1003,B12,Заказы!$O$4:$O$1003,"Ожидает самовывоза")) -> 0 | I12: =IF(B12="","",N(E12)-N(F12)-G12-H12) -> 4 | J12: =IF(B12="","",SUMIFS(Заказы!$I$4:$I$1003,Заказы!$E$4:$E$1003,B12,Заказы!$O$4:$O$1003,"Выполнен")) -> 0 | K12: =IF(B12="","",SUMIFS(Заказы!$M$4:$M$1003,Заказы!$E$4:$E$1003,B12,Заказы!$O$4:$O$1003,"Выполнен")) -> 0 | L12: =IF(B12="","",SUMIFS(Заказы!$I$4:$I$1003,Заказы!$E$4:$E$1003,B12,Заказы!$O$4:$O$1003,"Ожидает отправки")+SUMIFS(Заказы!$I$4:$I$1003,Заказы!$E$4:$E$1003,B12,Заказы!$O$4:$O$1003,"Отправлен (в пути)")+SUMIFS(Заказы!$I$4:$I$1003,Заказы!$E$4:$E$1003,B12,Заказы!$O$4:$O$1003,"Ожидает самовывоза")) -> 0 | M12: =IF(OR(B12="",N(J12)=0),"",K12/J12)
A13: =IF(B13="","",ROW()-3) -> 10 | B13: Цинк | C13: 1000 | D13: 1700 | E13: 5 | F13: 2 | G13: =IF(B13="","",SUMIFS(Заказы!$F$4:$F$1003,Заказы!$E$4:$E$1003,B13,Заказы!$O$4:$O$1003,"Выполнен")) -> 0 | H13: =IF(B13="","",SUMIFS(Заказы!$F$4:$F$1003,Заказы!$E$4:$E$1003,B13,Заказы!$O$4:$O$1003,"Ожидает отправки")+SUMIFS(Заказы!$F$4:$F$1003,Заказы!$E$4:$E$1003,B13,Заказы!$O$4:$O$1003,"Отправлен (в пути)")+SUMIFS(Заказы!$F$4:$F$1003,Заказы!$E$4:$E$1003,B13,Заказы!$O$4:$O$1003,"Ожидает самовывоза")) -> 1 | I13: =IF(B13="","",N(E13)-N(F13)-G13-H13) -> 2 | J13: =IF(B13="","",SUMIFS(Заказы!$I$4:$I$1003,Заказы!$E$4:$E$1003,B13,Заказы!$O$4:$O$1003,"Выполнен")) -> 0 | K13: =IF(B13="","",SUMIFS(Заказы!$M$4:$M$1003,Заказы!$E$4:$E$1003,B13,Заказы!$O$4:$O$1003,"Выполнен")) -> 0 | L13: =IF(B13="","",SUMIFS(Заказы!$I$4:$I$1003,Заказы!$E$4:$E$1003,B13,Заказы!$O$4:$O$1003,"Ожидает отправки")+SUMIFS(Заказы!$I$4:$I$1003,Заказы!$E$4:$E$1003,B13,Заказы!$O$4:$O$1003,"Отправлен (в пути)")+SUMIFS(Заказы!$I$4:$I$1003,Заказы!$E$4:$E$1003,B13,Заказы!$O$4:$O$1003,"Ожидает самовывоза")) -> 1700 | M13: =IF(OR(B13="",N(J13)=0),"",K13/J13)
A14: =IF(B14="","",ROW()-3) -> 11 | B14: Бца | C14: 1150 | D14: 2000 | E14: 6 | F14: 2 | G14: =IF(B14="","",SUMIFS(Заказы!$F$4:$F$1003,Заказы!$E$4:$E$1003,B14,Заказы!$O$4:$O$1003,"Выполнен")) -> 0 | H14: =IF(B14="","",SUMIFS(Заказы!$F$4:$F$1003,Заказы!$E$4:$E$1003,B14,Заказы!$O$4:$O$1003,"Ожидает отправки")+SUMIFS(Заказы!$F$4:$F$1003,Заказы!$E$4:$E$1003,B14,Заказы!$O$4:$O$1003,"Отправлен (в пути)")+SUMIFS(Заказы!$F$4:$F$1003,Заказы!$E$4:$E$1003,B14,Заказы!$O$4:$O$1003,"Ожидает самовывоза")) -> 0 | I14: =IF(B14="","",N(E14)-N(F14)-G14-H14) -> 4 | J14: =IF(B14="","",SUMIFS(Заказы!$I$4:$I$1003,Заказы!$E$4:$E$1003,B14,Заказы!$O$4:$O$1003,"Выполнен")) -> 0 | K14: =IF(B14="","",SUMIFS(Заказы!$M$4:$M$1003,Заказы!$E$4:$E$1003,B14,Заказы!$O$4:$O$1003,"Выполнен")) -> 0 | L14: =IF(B14="","",SUMIFS(Заказы!$I$4:$I$1003,Заказы!$E$4:$E$1003,B14,Заказы!$O$4:$O$1003,"Ожидает отправки")+SUMIFS(Заказы!$I$4:$I$1003,Заказы!$E$4:$E$1003,B14,Заказы!$O$4:$O$1003,"Отправлен (в пути)")+SUMIFS(Заказы!$I$4:$I$1003,Заказы!$E$4:$E$1003,B14,Заказы!$O$4:$O$1003,"Ожидает самовывоза")) -> 0 | M14: =IF(OR(B14="",N(J14)=0),"",K14/J14)
A15: =IF(B15="","",ROW()-3) -> 12 | B15: Креатин 600гр | C15: 1100 | D15: 2000 | E15: 3 | F15: 1 | G15: =IF(B15="","",SUMIFS(Заказы!$F$4:$F$1003,Заказы!$E$4:$E$1003,B15,Заказы!$O$4:$O$1003,"Выполнен")) -> 0 | H15: =IF(B15="","",SUMIFS(Заказы!$F$4:$F$1003,Заказы!$E$4:$E$1003,B15,Заказы!$O$4:$O$1003,"Ожидает отправки")+SUMIFS(Заказы!$F$4:$F$1003,Заказы!$E$4:$E$1003,B15,Заказы!$O$4:$O$1003,"Отправлен (в пути)")+SUMIFS(Заказы!$F$4:$F$1003,Заказы!$E$4:$E$1003,B15,Заказы!$O$4:$O$1003,"Ожидает самовывоза")) -> 0 | I15: =IF(B15="","",N(E15)-N(F15)-G15-H15) -> 2 | J15: =IF(B15="","",SUMIFS(Заказы!$I$4:$I$1003,Заказы!$E$4:$E$1003,B15,Заказы!$O$4:$O$1003,"Выполнен")) -> 0 | K15: =IF(B15="","",SUMIFS(Заказы!$M$4:$M$1003,Заказы!$E$4:$E$1003,B15,Заказы!$O$4:$O$1003,"Выполнен")) -> 0 | L15: =IF(B15="","",SUMIFS(Заказы!$I$4:$I$1003,Заказы!$E$4:$E$1003,B15,Заказы!$O$4:$O$1003,"Ожидает отправки")+SUMIFS(Заказы!$I$4:$I$1003,Заказы!$E$4:$E$1003,B15,Заказы!$O$4:$O$1003,"Отправлен (в пути)")+SUMIFS(Заказы!$I$4:$I$1003,Заказы!$E$4:$E$1003,B15,Заказы!$O$4:$O$1003,"Ожидает самовывоза")) -> 0 | M15: =IF(OR(B15="",N(J15)=0),"",K15/J15)
A16: =IF(B16="","",ROW()-3) -> 13 | B16: Креатин 300гр | C16: 650 | D16: 1200 | E16: 4 | G16: =IF(B16="","",SUMIFS(Заказы!$F$4:$F$1003,Заказы!$E$4:$E$1003,B16,Заказы!$O$4:$O$1003,"Выполнен")) -> 0 | H16: =IF(B16="","",SUMIFS(Заказы!$F$4:$F$1003,Заказы!$E$4:$E$1003,B16,Заказы!$O$4:$O$1003,"Ожидает отправки")+SUMIFS(Заказы!$F$4:$F$1003,Заказы!$E$4:$E$1003,B16,Заказы!$O$4:$O$1003,"Отправлен (в пути)")+SUMIFS(Заказы!$F$4:$F$1003,Заказы!$E$4:$E$1003,B16,Заказы!$O$4:$O$1003,"Ожидает самовывоза")) -> 0 | I16: =IF(B16="","",N(E16)-N(F16)-G16-H16) -> 4 | J16: =IF(B16="","",SUMIFS(Заказы!$I$4:$I$1003,Заказы!$E$4:$E$1003,B16,Заказы!$O$4:$O$1003,"Выполнен")) -> 0 | K16: =IF(B16="","",SUMIFS(Заказы!$M$4:$M$1003,Заказы!$E$4:$E$1003,B16,Заказы!$O$4:$O$1003,"Выполнен")) -> 0 | L16: =IF(B16="","",SUMIFS(Заказы!$I$4:$I$1003,Заказы!$E$4:$E$1003,B16,Заказы!$O$4:$O$1003,"Ожидает отправки")+SUMIFS(Заказы!$I$4:$I$1003,Заказы!$E$4:$E$1003,B16,Заказы!$O$4:$O$1003,"Отправлен (в пути)")+SUMIFS(Заказы!$I$4:$I$1003,Заказы!$E$4:$E$1003,B16,Заказы!$O$4:$O$1003,"Ожидает самовывоза")) -> 0 | M16: =IF(OR(B16="",N(J16)=0),"",K16/J16)
A17: =IF(B17="","",ROW()-3) -> 14 | B17: Пау дарко | C17: 1000 | D17: 1700 | E17: 5 | G17: =IF(B17="","",SUMIFS(Заказы!$F$4:$F$1003,Заказы!$E$4:$E$1003,B17,Заказы!$O$4:$O$1003,"Выполнен")) -> 0 | H17: =IF(B17="","",SUMIFS(Заказы!$F$4:$F$1003,Заказы!$E$4:$E$1003,B17,Заказы!$O$4:$O$1003,"Ожидает отправки")+SUMIFS(Заказы!$F$4:$F$1003,Заказы!$E$4:$E$1003,B17,Заказы!$O$4:$O$1003,"Отправлен (в пути)")+SUMIFS(Заказы!$F$4:$F$1003,Заказы!$E$4:$E$1003,B17,Заказы!$O$4:$O$1003,"Ожидает самовывоза")) -> 0 | I17: =IF(B17="","",N(E17)-N(F17)-G17-H17) -> 5 | J17: =IF(B17="","",SUMIFS(Заказы!$I$4:$I$1003,Заказы!$E$4:$E$1003,B17,Заказы!$O$4:$O$1003,"Выполнен")) -> 0 | K17: =IF(B17="","",SUMIFS(Заказы!$M$4:$M$1003,Заказы!$E$4:$E$1003,B17,Заказы!$O$4:$O$1003,"Выполнен")) -> 0 | L17: =IF(B17="","",SUMIFS(Заказы!$I$4:$I$1003,Заказы!$E$4:$E$1003,B17,Заказы!$O$4:$O$1003,"Ожидает отправки")+SUMIFS(Заказы!$I$4:$I$1003,Заказы!$E$4:$E$1003,B17,Заказы!$O$4:$O$1003,"Отправлен (в пути)")+SUMIFS(Заказы!$I$4:$I$1003,Заказы!$E$4:$E$1003,B17,Заказы!$O$4:$O$1003,"Ожидает самовывоза")) -> 0 | M17: =IF(OR(B17="",N(J17)=0),"",K17/J17)
A18: =IF(B18="","",ROW()-3) -> 15 | B18: L-лизин | C18: 900 | D18: 1800 | E18: 5 | G18: =IF(B18="","",SUMIFS(Заказы!$F$4:$F$1003,Заказы!$E$4:$E$1003,B18,Заказы!$O$4:$O$1003,"Выполнен")) -> 0 | H18: =IF(B18="","",SUMIFS(Заказы!$F$4:$F$1003,Заказы!$E$4:$E$1003,B18,Заказы!$O$4:$O$1003,"Ожидает отправки")+SUMIFS(Заказы!$F$4:$F$1003,Заказы!$E$4:$E$1003,B18,Заказы!$O$4:$O$1003,"Отправлен (в пути)")+SUMIFS(Заказы!$F$4:$F$1003,Заказы!$E$4:$E$1003,B18,Заказы!$O$4:$O$1003,"Ожидает самовывоза")) -> 0 | I18: =IF(B18="","",N(E18)-N(F18)-G18-H18) -> 5 | J18: =IF(B18="","",SUMIFS(Заказы!$I$4:$I$1003,Заказы!$E$4:$E$1003,B18,Заказы!$O$4:$O$1003,"Выполнен")) -> 0 | K18: =IF(B18="","",SUMIFS(Заказы!$M$4:$M$1003,Заказы!$E$4:$E$1003,B18,Заказы!$O$4:$O$1003,"Выполнен")) -> 0 | L18: =IF(B18="","",SUMIFS(Заказы!$I$4:$I$1003,Заказы!$E$4:$E$1003,B18,Заказы!$O$4:$O$1003,"Ожидает отправки")+SUMIFS(Заказы!$I$4:$I$1003,Заказы!$E$4:$E$1003,B18,Заказы!$O$4:$O$1003,"Отправлен (в пути)")+SUMIFS(Заказы!$I$4:$I$1003,Заказы!$E$4:$E$1003,B18,Заказы!$O$4:$O$1003,"Ожидает самовывоза")) -> 0 | M18: =IF(OR(B18="",N(J18)=0),"",K18/J18)
A19: =IF(B19="","",ROW()-3) -> 16 | B19: SI комплекс | C19: 1000 | D19: 1800 | E19: 5 | G19: =IF(B19="","",SUMIFS(Заказы!$F$4:$F$1003,Заказы!$E$4:$E$1003,B19,Заказы!$O$4:$O$1003,"Выполнен")) -> 0 | H19: =IF(B19="","",SUMIFS(Заказы!$F$4:$F$1003,Заказы!$E$4:$E$1003,B19,Заказы!$O$4:$O$1003,"Ожидает отправки")+SUMIFS(Заказы!$F$4:$F$1003,Заказы!$E$4:$E$1003,B19,Заказы!$O$4:$O$1003,"Отправлен (в пути)")+SUMIFS(Заказы!$F$4:$F$1003,Заказы!$E$4:$E$1003,B19,Заказы!$O$4:$O$1003,"Ожидает самовывоза")) -> 0 | I19: =IF(B19="","",N(E19)-N(F19)-G19-H19) -> 5 | J19: =IF(B19="","",SUMIFS(Заказы!$I$4:$I$1003,Заказы!$E$4:$E$1003,B19,Заказы!$O$4:$O$1003,"Выполнен")) -> 0 | K19: =IF(B19="","",SUMIFS(Заказы!$M$4:$M$1003,Заказы!$E$4:$E$1003,B19,Заказы!$O$4:$O$1003,"Выполнен")) -> 0 | L19: =IF(B19="","",SUMIFS(Заказы!$I$4:$I$1003,Заказы!$E$4:$E$1003,B19,Заказы!$O$4:$O$1003,"Ожидает отправки")+SUMIFS(Заказы!$I$4:$I$1003,Заказы!$E$4:$E$1003,B19,Заказы!$O$4:$O$1003,"Отправлен (в пути)")+SUMIFS(Заказы!$I$4:$I$1003,Заказы!$E$4:$E$1003,B19,Заказы!$O$4:$O$1003,"Ожидает самовывоза")) -> 0 | M19: =IF(OR(B19="",N(J19)=0),"",K19/J19)
A20: =IF(B20="","",ROW()-3) -> 17 | B20: Инозитол | C20: 1100 | D20: 2800 | E20: 5 | G20: =IF(B20="","",SUMIFS(Заказы!$F$4:$F$1003,Заказы!$E$4:$E$1003,B20,Заказы!$O$4:$O$1003,"Выполнен")) -> 0 | H20: =IF(B20="","",SUMIFS(Заказы!$F$4:$F$1003,Заказы!$E$4:$E$1003,B20,Заказы!$O$4:$O$1003,"Ожидает отправки")+SUMIFS(Заказы!$F$4:$F$1003,Заказы!$E$4:$E$1003,B20,Заказы!$O$4:$O$1003,"Отправлен (в пути)")+SUMIFS(Заказы!$F$4:$F$1003,Заказы!$E$4:$E$1003,B20,Заказы!$O$4:$O$1003,"Ожидает самовывоза")) -> 0 | I20: =IF(B20="","",N(E20)-N(F20)-G20-H20) -> 5 | J20: =IF(B20="","",SUMIFS(Заказы!$I$4:$I$1003,Заказы!$E$4:$E$1003,B20,Заказы!$O$4:$O$1003,"Выполнен")) -> 0 | K20: =IF(B20="","",SUMIFS(Заказы!$M$4:$M$1003,Заказы!$E$4:$E$1003,B20,Заказы!$O$4:$O$1003,"Выполнен")) -> 0 | L20: =IF(B20="","",SUMIFS(Заказы!$I$4:$I$1003,Заказы!$E$4:$E$1003,B20,Заказы!$O$4:$O$1003,"Ожидает отправки")+SUMIFS(Заказы!$I$4:$I$1003,Заказы!$E$4:$E$1003,B20,Заказы!$O$4:$O$1003,"Отправлен (в пути)")+SUMIFS(Заказы!$I$4:$I$1003,Заказы!$E$4:$E$1003,B20,Заказы!$O$4:$O$1003,"Ожидает самовывоза")) -> 0 | M20: =IF(OR(B20="",N(J20)=0),"",K20/J20)
A21: =IF(B21="","",ROW()-3) -> 18 | B21: Гиолурованя к-с | C21: 1150 | D21: 2300 | E21: 5 | G21: =IF(B21="","",SUMIFS(Заказы!$F$4:$F$1003,Заказы!$E$4:$E$1003,B21,Заказы!$O$4:$O$1003,"Выполнен")) -> 0 | H21: =IF(B21="","",SUMIFS(Заказы!$F$4:$F$1003,Заказы!$E$4:$E$1003,B21,Заказы!$O$4:$O$1003,"Ожидает отправки")+SUMIFS(Заказы!$F$4:$F$1003,Заказы!$E$4:$E$1003,B21,Заказы!$O$4:$O$1003,"Отправлен (в пути)")+SUMIFS(Заказы!$F$4:$F$1003,Заказы!$E$4:$E$1003,B21,Заказы!$O$4:$O$1003,"Ожидает самовывоза")) -> 0 | I21: =IF(B21="","",N(E21)-N(F21)-G21-H21) -> 5 | J21: =IF(B21="","",SUMIFS(Заказы!$I$4:$I$1003,Заказы!$E$4:$E$1003,B21,Заказы!$O$4:$O$1003,"Выполнен")) -> 0 | K21: =IF(B21="","",SUMIFS(Заказы!$M$4:$M$1003,Заказы!$E$4:$E$1003,B21,Заказы!$O$4:$O$1003,"Выполнен")) -> 0 | L21: =IF(B21="","",SUMIFS(Заказы!$I$4:$I$1003,Заказы!$E$4:$E$1003,B21,Заказы!$O$4:$O$1003,"Ожидает отправки")+SUMIFS(Заказы!$I$4:$I$1003,Заказы!$E$4:$E$1003,B21,Заказы!$O$4:$O$1003,"Отправлен (в пути)")+SUMIFS(Заказы!$I$4:$I$1003,Заказы!$E$4:$E$1003,B21,Заказы!$O$4:$O$1003,"Ожидает самовывоза")) -> 0 | M21: =IF(OR(B21="",N(J21)=0),"",K21/J21)
A22: =IF(B22="","",ROW()-3) -> 19 | B22: Компл.вит. Ж | C22: 1000 | D22: 2000 | E22: 5 | G22: =IF(B22="","",SUMIFS(Заказы!$F$4:$F$1003,Заказы!$E$4:$E$1003,B22,Заказы!$O$4:$O$1003,"Выполнен")) -> 0 | H22: =IF(B22="","",SUMIFS(Заказы!$F$4:$F$1003,Заказы!$E$4:$E$1003,B22,Заказы!$O$4:$O$1003,"Ожидает отправки")+SUMIFS(Заказы!$F$4:$F$1003,Заказы!$E$4:$E$1003,B22,Заказы!$O$4:$O$1003,"Отправлен (в пути)")+SUMIFS(Заказы!$F$4:$F$1003,Заказы!$E$4:$E$1003,B22,Заказы!$O$4:$O$1003,"Ожидает самовывоза")) -> 0 | I22: =IF(B22="","",N(E22)-N(F22)-G22-H22) -> 5 | J22: =IF(B22="","",SUMIFS(Заказы!$I$4:$I$1003,Заказы!$E$4:$E$1003,B22,Заказы!$O$4:$O$1003,"Выполнен")) -> 0 | K22: =IF(B22="","",SUMIFS(Заказы!$M$4:$M$1003,Заказы!$E$4:$E$1003,B22,Заказы!$O$4:$O$1003,"Выполнен")) -> 0 | L22: =IF(B22="","",SUMIFS(Заказы!$I$4:$I$1003,Заказы!$E$4:$E$1003,B22,Заказы!$O$4:$O$1003,"Ожидает отправки")+SUMIFS(Заказы!$I$4:$I$1003,Заказы!$E$4:$E$1003,B22,Заказы!$O$4:$O$1003,"Отправлен (в пути)")+SUMIFS(Заказы!$I$4:$I$1003,Заказы!$E$4:$E$1003,B22,Заказы!$O$4:$O$1003,"Ожидает самовывоза")) -> 0 | M22: =IF(OR(B22="",N(J22)=0),"",K22/J22)
A23: =IF(B23="","",ROW()-3) -> 20 | B23: Reta 20mg | C23: 7000 | D23: 12500 | E23: 2 | F23: 1 | G23: =IF(B23="","",SUMIFS(Заказы!$F$4:$F$1003,Заказы!$E$4:$E$1003,B23,Заказы!$O$4:$O$1003,"Выполнен")) -> 0 | H23: =IF(B23="","",SUMIFS(Заказы!$F$4:$F$1003,Заказы!$E$4:$E$1003,B23,Заказы!$O$4:$O$1003,"Ожидает отправки")+SUMIFS(Заказы!$F$4:$F$1003,Заказы!$E$4:$E$1003,B23,Заказы!$O$4:$O$1003,"Отправлен (в пути)")+SUMIFS(Заказы!$F$4:$F$1003,Заказы!$E$4:$E$1003,B23,Заказы!$O$4:$O$1003,"Ожидает самовывоза")) -> 1 | I23: =IF(B23="","",N(E23)-N(F23)-G23-H23) -> 0 | J23: =IF(B23="","",SUMIFS(Заказы!$I$4:$I$1003,Заказы!$E$4:$E$1003,B23,Заказы!$O$4:$O$1003,"Выполнен")) -> 0 | K23: =IF(B23="","",SUMIFS(Заказы!$M$4:$M$1003,Заказы!$E$4:$E$1003,B23,Заказы!$O$4:$O$1003,"Выполнен")) -> 0 | L23: =IF(B23="","",SUMIFS(Заказы!$I$4:$I$1003,Заказы!$E$4:$E$1003,B23,Заказы!$O$4:$O$1003,"Ожидает отправки")+SUMIFS(Заказы!$I$4:$I$1003,Заказы!$E$4:$E$1003,B23,Заказы!$O$4:$O$1003,"Отправлен (в пути)")+SUMIFS(Заказы!$I$4:$I$1003,Заказы!$E$4:$E$1003,B23,Заказы!$O$4:$O$1003,"Ожидает самовывоза")) -> 11500 | M23: =IF(OR(B23="",N(J23)=0),"",K23/J23)
A24: =IF(B24="","",ROW()-3) -> 21 | B24: Reta 60mg | C24: 14500 | D24: 25500 | E24: 2 | F24: 2 | G24: =IF(B24="","",SUMIFS(Заказы!$F$4:$F$1003,Заказы!$E$4:$E$1003,B24,Заказы!$O$4:$O$1003,"Выполнен")) -> 0 | H24: =IF(B24="","",SUMIFS(Заказы!$F$4:$F$1003,Заказы!$E$4:$E$1003,B24,Заказы!$O$4:$O$1003,"Ожидает отправки")+SUMIFS(Заказы!$F$4:$F$1003,Заказы!$E$4:$E$1003,B24,Заказы!$O$4:$O$1003,"Отправлен (в пути)")+SUMIFS(Заказы!$F$4:$F$1003,Заказы!$E$4:$E$1003,B24,Заказы!$O$4:$O$1003,"Ожидает самовывоза")) -> 0 | I24: =IF(B24="","",N(E24)-N(F24)-G24-H24) -> 0 | J24: =IF(B24="","",SUMIFS(Заказы!$I$4:$I$1003,Заказы!$E$4:$E$1003,B24,Заказы!$O$4:$O$1003,"Выполнен")) -> 0 | K24: =IF(B24="","",SUMIFS(Заказы!$M$4:$M$1003,Заказы!$E$4:$E$1003,B24,Заказы!$O$4:$O$1003,"Выполнен")) -> 0 | L24: =IF(B24="","",SUMIFS(Заказы!$I$4:$I$1003,Заказы!$E$4:$E$1003,B24,Заказы!$O$4:$O$1003,"Ожидает отправки")+SUMIFS(Заказы!$I$4:$I$1003,Заказы!$E$4:$E$1003,B24,Заказы!$O$4:$O$1003,"Отправлен (в пути)")+SUMIFS(Заказы!$I$4:$I$1003,Заказы!$E$4:$E$1003,B24,Заказы!$O$4:$O$1003,"Ожидает самовывоза")) -> 0 | M24: =IF(OR(B24="",N(J24)=0),"",K24/J24)
A25: =IF(B25="","",ROW()-3) -> 22 | B25: Reta 80mg | C25: 16500 | D25: 28000 | E25: 2 | F25: 2 | G25: =IF(B25="","",SUMIFS(Заказы!$F$4:$F$1003,Заказы!$E$4:$E$1003,B25,Заказы!$O$4:$O$1003,"Выполнен")) -> 0 | H25: =IF(B25="","",SUMIFS(Заказы!$F$4:$F$1003,Заказы!$E$4:$E$1003,B25,Заказы!$O$4:$O$1003,"Ожидает отправки")+SUMIFS(Заказы!$F$4:$F$1003,Заказы!$E$4:$E$1003,B25,Заказы!$O$4:$O$1003,"Отправлен (в пути)")+SUMIFS(Заказы!$F$4:$F$1003,Заказы!$E$4:$E$1003,B25,Заказы!$O$4:$O$1003,"Ожидает самовывоза")) -> 0 | I25: =IF(B25="","",N(E25)-N(F25)-G25-H25) -> 0 | J25: =IF(B25="","",SUMIFS(Заказы!$I$4:$I$1003,Заказы!$E$4:$E$1003,B25,Заказы!$O$4:$O$1003,"Выполнен")) -> 0 | K25: =IF(B25="","",SUMIFS(Заказы!$M$4:$M$1003,Заказы!$E$4:$E$1003,B25,Заказы!$O$4:$O$1003,"Выполнен")) -> 0 | L25: =IF(B25="","",SUMIFS(Заказы!$I$4:$I$1003,Заказы!$E$4:$E$1003,B25,Заказы!$O$4:$O$1003,"Ожидает отправки")+SUMIFS(Заказы!$I$4:$I$1003,Заказы!$E$4:$E$1003,B25,Заказы!$O$4:$O$1003,"Отправлен (в пути)")+SUMIFS(Заказы!$I$4:$I$1003,Заказы!$E$4:$E$1003,B25,Заказы!$O$4:$O$1003,"Ожидает самовывоза")) -> 0 | M25: =IF(OR(B25="",N(J25)=0),"",K25/J25)
A26: =IF(B26="","",ROW()-3) -> 23 | B26: Gen.Ручки Tirz | C26: 9500 | D26: 16500 | E26: 2 | F26: 1 | G26: =IF(B26="","",SUMIFS(Заказы!$F$4:$F$1003,Заказы!$E$4:$E$1003,B26,Заказы!$O$4:$O$1003,"Выполнен")) -> 0 | H26: =IF(B26="","",SUMIFS(Заказы!$F$4:$F$1003,Заказы!$E$4:$E$1003,B26,Заказы!$O$4:$O$1003,"Ожидает отправки")+SUMIFS(Заказы!$F$4:$F$1003,Заказы!$E$4:$E$1003,B26,Заказы!$O$4:$O$1003,"Отправлен (в пути)")+SUMIFS(Заказы!$F$4:$F$1003,Заказы!$E$4:$E$1003,B26,Заказы!$O$4:$O$1003,"Ожидает самовывоза")) -> 0 | I26: =IF(B26="","",N(E26)-N(F26)-G26-H26) -> 1 | J26: =IF(B26="","",SUMIFS(Заказы!$I$4:$I$1003,Заказы!$E$4:$E$1003,B26,Заказы!$O$4:$O$1003,"Выполнен")) -> 0 | K26: =IF(B26="","",SUMIFS(Заказы!$M$4:$M$1003,Заказы!$E$4:$E$1003,B26,Заказы!$O$4:$O$1003,"Выполнен")) -> 0 | L26: =IF(B26="","",SUMIFS(Заказы!$I$4:$I$1003,Заказы!$E$4:$E$1003,B26,Заказы!$O$4:$O$1003,"Ожидает отправки")+SUMIFS(Заказы!$I$4:$I$1003,Заказы!$E$4:$E$1003,B26,Заказы!$O$4:$O$1003,"Отправлен (в пути)")+SUMIFS(Заказы!$I$4:$I$1003,Заказы!$E$4:$E$1003,B26,Заказы!$O$4:$O$1003,"Ожидает самовывоза")) -> 0 | M26: =IF(OR(B26="",N(J26)=0),"",K26/J26)
A27: =IF(B27="","",ROW()-3) -> 24 | B27: Gen.Ручки Reta | C27: 9500 | D27: 16500 | E27: 4 | F27: 2 | G27: =IF(B27="","",SUMIFS(Заказы!$F$4:$F$1003,Заказы!$E$4:$E$1003,B27,Заказы!$O$4:$O$1003,"Выполнен")) -> 0 | H27: =IF(B27="","",SUMIFS(Заказы!$F$4:$F$1003,Заказы!$E$4:$E$1003,B27,Заказы!$O$4:$O$1003,"Ожидает отправки")+SUMIFS(Заказы!$F$4:$F$1003,Заказы!$E$4:$E$1003,B27,Заказы!$O$4:$O$1003,"Отправлен (в пути)")+SUMIFS(Заказы!$F$4:$F$1003,Заказы!$E$4:$E$1003,B27,Заказы!$O$4:$O$1003,"Ожидает самовывоза")) -> 0 | I27: =IF(B27="","",N(E27)-N(F27)-G27-H27) -> 2 | J27: =IF(B27="","",SUMIFS(Заказы!$I$4:$I$1003,Заказы!$E$4:$E$1003,B27,Заказы!$O$4:$O$1003,"Выполнен")) -> 0 | K27: =IF(B27="","",SUMIFS(Заказы!$M$4:$M$1003,Заказы!$E$4:$E$1003,B27,Заказы!$O$4:$O$1003,"Выполнен")) -> 0 | L27: =IF(B27="","",SUMIFS(Заказы!$I$4:$I$1003,Заказы!$E$4:$E$1003,B27,Заказы!$O$4:$O$1003,"Ожидает отправки")+SUMIFS(Заказы!$I$4:$I$1003,Заказы!$E$4:$E$1003,B27,Заказы!$O$4:$O$1003,"Отправлен (в пути)")+SUMIFS(Заказы!$I$4:$I$1003,Заказы!$E$4:$E$1003,B27,Заказы!$O$4:$O$1003,"Ожидает самовывоза")) -> 0 | M27: =IF(OR(B27="",N(J27)=0),"",K27/J27)
A28: =IF(B28="","",ROW()-3) -> 25 | B28: Gen.Ручки mots | C28: 15000 | D28: 25000 | E28: 2 | F28: 2 | G28: =IF(B28="","",SUMIFS(Заказы!$F$4:$F$1003,Заказы!$E$4:$E$1003,B28,Заказы!$O$4:$O$1003,"Выполнен")) -> 0 | H28: =IF(B28="","",SUMIFS(Заказы!$F$4:$F$1003,Заказы!$E$4:$E$1003,B28,Заказы!$O$4:$O$1003,"Ожидает отправки")+SUMIFS(Заказы!$F$4:$F$1003,Заказы!$E$4:$E$1003,B28,Заказы!$O$4:$O$1003,"Отправлен (в пути)")+SUMIFS(Заказы!$F$4:$F$1003,Заказы!$E$4:$E$1003,B28,Заказы!$O$4:$O$1003,"Ожидает самовывоза")) -> 0 | I28: =IF(B28="","",N(E28)-N(F28)-G28-H28) -> 0 | J28: =IF(B28="","",SUMIFS(Заказы!$I$4:$I$1003,Заказы!$E$4:$E$1003,B28,Заказы!$O$4:$O$1003,"Выполнен")) -> 0 | K28: =IF(B28="","",SUMIFS(Заказы!$M$4:$M$1003,Заказы!$E$4:$E$1003,B28,Заказы!$O$4:$O$1003,"Выполнен")) -> 0 | L28: =IF(B28="","",SUMIFS(Заказы!$I$4:$I$1003,Заказы!$E$4:$E$1003,B28,Заказы!$O$4:$O$1003,"Ожидает отправки")+SUMIFS(Заказы!$I$4:$I$1003,Заказы!$E$4:$E$1003,B28,Заказы!$O$4:$O$1003,"Отправлен (в пути)")+SUMIFS(Заказы!$I$4:$I$1003,Заказы!$E$4:$E$1003,B28,Заказы!$O$4:$O$1003,"Ожидает самовывоза")) -> 0 | M28: =IF(OR(B28="",N(J28)=0),"",K28/J28)
A29: =IF(B29="","",ROW()-3) -> 26 | B29: Aicar | C29: 6500 | D29: 12500 | E29: 2 | F29: 2 | G29: =IF(B29="","",SUMIFS(Заказы!$F$4:$F$1003,Заказы!$E$4:$E$1003,B29,Заказы!$O$4:$O$1003,"Выполнен")) -> 0 | H29: =IF(B29="","",SUMIFS(Заказы!$F$4:$F$1003,Заказы!$E$4:$E$1003,B29,Заказы!$O$4:$O$1003,"Ожидает отправки")+SUMIFS(Заказы!$F$4:$F$1003,Заказы!$E$4:$E$1003,B29,Заказы!$O$4:$O$1003,"Отправлен (в пути)")+SUMIFS(Заказы!$F$4:$F$1003,Заказы!$E$4:$E$1003,B29,Заказы!$O$4:$O$1003,"Ожидает самовывоза")) -> 0 | I29: =IF(B29="","",N(E29)-N(F29)-G29-H29) -> 0 | J29: =IF(B29="","",SUMIFS(Заказы!$I$4:$I$1003,Заказы!$E$4:$E$1003,B29,Заказы!$O$4:$O$1003,"Выполнен")) -> 0 | K29: =IF(B29="","",SUMIFS(Заказы!$M$4:$M$1003,Заказы!$E$4:$E$1003,B29,Заказы!$O$4:$O$1003,"Выполнен")) -> 0 | L29: =IF(B29="","",SUMIFS(Заказы!$I$4:$I$1003,Заказы!$E$4:$E$1003,B29,Заказы!$O$4:$O$1003,"Ожидает отправки")+SUMIFS(Заказы!$I$4:$I$1003,Заказы!$E$4:$E$1003,B29,Заказы!$O$4:$O$1003,"Отправлен (в пути)")+SUMIFS(Заказы!$I$4:$I$1003,Заказы!$E$4:$E$1003,B29,Заказы!$O$4:$O$1003,"Ожидает самовывоза")) -> 0 | M29: =IF(OR(B29="",N(J29)=0),"",K29/J29)
A30: =IF(B30="","",ROW()-3) | G30: =IF(B30="","",SUMIFS(Заказы!$F$4:$F$1003,Заказы!$E$4:$E$1003,B30,Заказы!$O$4:$O$1003,"Выполнен")) | H30: =IF(B30="","",SUMIFS(Заказы!$F$4:$F$1003,Заказы!$E$4:$E$1003,B30,Заказы!$O$4:$O$1003,"Ожидает отправки")+SUMIFS(Заказы!$F$4:$F$1003,Заказы!$E$4:$E$1003,B30,Заказы!$O$4:$O$1003,"Отправлен (в пути)")+SUMIFS(Заказы!$F$4:$F$1003,Заказы!$E$4:$E$1003,B30,Заказы!$O$4:$O$1003,"Ожидает самовывоза")) | I30: =IF(B30="","",N(E30)-N(F30)-G30-H30) | J30: =IF(B30="","",SUMIFS(Заказы!$I$4:$I$1003,Заказы!$E$4:$E$1003,B30,Заказы!$O$4:$O$1003,"Выполнен")) | K30: =IF(B30="","",SUMIFS(Заказы!$M$4:$M$1003,Заказы!$E$4:$E$1003,B30,Заказы!$O$4:$O$1003,"Выполнен")) | L30: =IF(B30="","",SUMIFS(Заказы!$I$4:$I$1003,Заказы!$E$4:$E$1003,B30,Заказы!$O$4:$O$1003,"Ожидает отправки")+SUMIFS(Заказы!$I$4:$I$1003,Заказы!$E$4:$E$1003,B30,Заказы!$O$4:$O$1003,"Отправлен (в пути)")+SUMIFS(Заказы!$I$4:$I$1003,Заказы!$E$4:$E$1003,B30,Заказы!$O$4:$O$1003,"Ожидает самовывоза")) | M30: =IF(OR(B30="",N(J30)=0),"",K30/J30)
A31: =IF(B31="","",ROW()-3) | G31: =IF(B31="","",SUMIFS(Заказы!$F$4:$F$1003,Заказы!$E$4:$E$1003,B31,Заказы!$O$4:$O$1003,"Выполнен")) | H31: =IF(B31="","",SUMIFS(Заказы!$F$4:$F$1003,Заказы!$E$4:$E$1003,B31,Заказы!$O$4:$O$1003,"Ожидает отправки")+SUMIFS(Заказы!$F$4:$F$1003,Заказы!$E$4:$E$1003,B31,Заказы!$O$4:$O$1003,"Отправлен (в пути)")+SUMIFS(Заказы!$F$4:$F$1003,Заказы!$E$4:$E$1003,B31,Заказы!$O$4:$O$1003,"Ожидает самовывоза")) | I31: =IF(B31="","",N(E31)-N(F31)-G31-H31) | J31: =IF(B31="","",SUMIFS(Заказы!$I$4:$I$1003,Заказы!$E$4:$E$1003,B31,Заказы!$O$4:$O$1003,"Выполнен")) | K31: =IF(B31="","",SUMIFS(Заказы!$M$4:$M$1003,Заказы!$E$4:$E$1003,B31,Заказы!$O$4:$O$1003,"Выполнен")) | L31: =IF(B31="","",SUMIFS(Заказы!$I$4:$I$1003,Заказы!$E$4:$E$1003,B31,Заказы!$O$4:$O$1003,"Ожидает отправки")+SUMIFS(Заказы!$I$4:$I$1003,Заказы!$E$4:$E$1003,B31,Заказы!$O$4:$O$1003,"Отправлен (в пути)")+SUMIFS(Заказы!$I$4:$I$1003,Заказы!$E$4:$E$1003,B31,Заказы!$O$4:$O$1003,"Ожидает самовывоза")) | M31: =IF(OR(B31="",N(J31)=0),"",K31/J31)
A32: =IF(B32="","",ROW()-3) | G32: =IF(B32="","",SUMIFS(Заказы!$F$4:$F$1003,Заказы!$E$4:$E$1003,B32,Заказы!$O$4:$O$1003,"Выполнен")) | H32: =IF(B32="","",SUMIFS(Заказы!$F$4:$F$1003,Заказы!$E$4:$E$1003,B32,Заказы!$O$4:$O$1003,"Ожидает отправки")+SUMIFS(Заказы!$F$4:$F$1003,Заказы!$E$4:$E$1003,B32,Заказы!$O$4:$O$1003,"Отправлен (в пути)")+SUMIFS(Заказы!$F$4:$F$1003,Заказы!$E$4:$E$1003,B32,Заказы!$O$4:$O$1003,"Ожидает самовывоза")) | I32: =IF(B32="","",N(E32)-N(F32)-G32-H32) | J32: =IF(B32="","",SUMIFS(Заказы!$I$4:$I$1003,Заказы!$E$4:$E$1003,B32,Заказы!$O$4:$O$1003,"Выполнен")) | K32: =IF(B32="","",SUMIFS(Заказы!$M$4:$M$1003,Заказы!$E$4:$E$1003,B32,Заказы!$O$4:$O$1003,"Выполнен")) | L32: =IF(B32="","",SUMIFS(Заказы!$I$4:$I$1003,Заказы!$E$4:$E$1003,B32,Заказы!$O$4:$O$1003,"Ожидает отправки")+SUMIFS(Заказы!$I$4:$I$1003,Заказы!$E$4:$E$1003,B32,Заказы!$O$4:$O$1003,"Отправлен (в пути)")+SUMIFS(Заказы!$I$4:$I$1003,Заказы!$E$4:$E$1003,B32,Заказы!$O$4:$O$1003,"Ожидает самовывоза")) | M32: =IF(OR(B32="",N(J32)=0),"",K32/J32)
A33: =IF(B33="","",ROW()-3) | G33: =IF(B33="","",SUMIFS(Заказы!$F$4:$F$1003,Заказы!$E$4:$E$1003,B33,Заказы!$O$4:$O$1003,"Выполнен")) | H33: =IF(B33="","",SUMIFS(Заказы!$F$4:$F$1003,Заказы!$E$4:$E$1003,B33,Заказы!$O$4:$O$1003,"Ожидает отправки")+SUMIFS(Заказы!$F$4:$F$1003,Заказы!$E$4:$E$1003,B33,Заказы!$O$4:$O$1003,"Отправлен (в пути)")+SUMIFS(Заказы!$F$4:$F$1003,Заказы!$E$4:$E$1003,B33,Заказы!$O$4:$O$1003,"Ожидает самовывоза")) | I33: =IF(B33="","",N(E33)-N(F33)-G33-H33) | J33: =IF(B33="","",SUMIFS(Заказы!$I$4:$I$1003,Заказы!$E$4:$E$1003,B33,Заказы!$O$4:$O$1003,"Выполнен")) | K33: =IF(B33="","",SUMIFS(Заказы!$M$4:$M$1003,Заказы!$E$4:$E$1003,B33,Заказы!$O$4:$O$1003,"Выполнен")) | L33: =IF(B33="","",SUMIFS(Заказы!$I$4:$I$1003,Заказы!$E$4:$E$1003,B33,Заказы!$O$4:$O$1003,"Ожидает отправки")+SUMIFS(Заказы!$I$4:$I$1003,Заказы!$E$4:$E$1003,B33,Заказы!$O$4:$O$1003,"Отправлен (в пути)")+SUMIFS(Заказы!$I$4:$I$1003,Заказы!$E$4:$E$1003,B33,Заказы!$O$4:$O$1003,"Ожидает самовывоза")) | M33: =IF(OR(B33="",N(J33)=0),"",K33/J33)
A34: =IF(B34="","",ROW()-3) | G34: =IF(B34="","",SUMIFS(Заказы!$F$4:$F$1003,Заказы!$E$4:$E$1003,B34,Заказы!$O$4:$O$1003,"Выполнен")) | H34: =IF(B34="","",SUMIFS(Заказы!$F$4:$F$1003,Заказы!$E$4:$E$1003,B34,Заказы!$O$4:$O$1003,"Ожидает отправки")+SUMIFS(Заказы!$F$4:$F$1003,Заказы!$E$4:$E$1003,B34,Заказы!$O$4:$O$1003,"Отправлен (в пути)")+SUMIFS(Заказы!$F$4:$F$1003,Заказы!$E$4:$E$1003,B34,Заказы!$O$4:$O$1003,"Ожидает самовывоза")) | I34: =IF(B34="","",N(E34)-N(F34)-G34-H34) | J34: =IF(B34="","",SUMIFS(Заказы!$I$4:$I$1003,Заказы!$E$4:$E$1003,B34,Заказы!$O$4:$O$1003,"Выполнен")) | K34: =IF(B34="","",SUMIFS(Заказы!$M$4:$M$1003,Заказы!$E$4:$E$1003,B34,Заказы!$O$4:$O$1003,"Выполнен")) | L34: =IF(B34="","",SUMIFS(Заказы!$I$4:$I$1003,Заказы!$E$4:$E$1003,B34,Заказы!$O$4:$O$1003,"Ожидает отправки")+SUMIFS(Заказы!$I$4:$I$1003,Заказы!$E$4:$E$1003,B34,Заказы!$O$4:$O$1003,"Отправлен (в пути)")+SUMIFS(Заказы!$I$4:$I$1003,Заказы!$E$4:$E$1003,B34,Заказы!$O$4:$O$1003,"Ожидает самовывоза")) | M34: =IF(OR(B34="",N(J34)=0),"",K34/J34)
A35: =IF(B35="","",ROW()-3) | G35: =IF(B35="","",SUMIFS(Заказы!$F$4:$F$1003,Заказы!$E$4:$E$1003,B35,Заказы!$O$4:$O$1003,"Выполнен")) | H35: =IF(B35="","",SUMIFS(Заказы!$F$4:$F$1003,Заказы!$E$4:$E$1003,B35,Заказы!$O$4:$O$1003,"Ожидает отправки")+SUMIFS(Заказы!$F$4:$F$1003,Заказы!$E$4:$E$1003,B35,Заказы!$O$4:$O$1003,"Отправлен (в пути)")+SUMIFS(Заказы!$F$4:$F$1003,Заказы!$E$4:$E$1003,B35,Заказы!$O$4:$O$1003,"Ожидает самовывоза")) | I35: =IF(B35="","",N(E35)-N(F35)-G35-H35) | J35: =IF(B35="","",SUMIFS(Заказы!$I$4:$I$1003,Заказы!$E$4:$E$1003,B35,Заказы!$O$4:$O$1003,"Выполнен")) | K35: =IF(B35="","",SUMIFS(Заказы!$M$4:$M$1003,Заказы!$E$4:$E$1003,B35,Заказы!$O$4:$O$1003,"Выполнен")) | L35: =IF(B35="","",SUMIFS(Заказы!$I$4:$I$1003,Заказы!$E$4:$E$1003,B35,Заказы!$O$4:$O$1003,"Ожидает отправки")+SUMIFS(Заказы!$I$4:$I$1003,Заказы!$E$4:$E$1003,B35,Заказы!$O$4:$O$1003,"Отправлен (в пути)")+SUMIFS(Заказы!$I$4:$I$1003,Заказы!$E$4:$E$1003,B35,Заказы!$O$4:$O$1003,"Ожидает самовывоза")) | M35: =IF(OR(B35="",N(J35)=0),"",K35/J35)
A36: =IF(B36="","",ROW()-3) | G36: =IF(B36="","",SUMIFS(Заказы!$F$4:$F$1003,Заказы!$E$4:$E$1003,B36,Заказы!$O$4:$O$1003,"Выполнен")) | H36: =IF(B36="","",SUMIFS(Заказы!$F$4:$F$1003,Заказы!$E$4:$E$1003,B36,Заказы!$O$4:$O$1003,"Ожидает отправки")+SUMIFS(Заказы!$F$4:$F$1003,Заказы!$E$4:$E$1003,B36,Заказы!$O$4:$O$1003,"Отправлен (в пути)")+SUMIFS(Заказы!$F$4:$F$1003,Заказы!$E$4:$E$1003,B36,Заказы!$O$4:$O$1003,"Ожидает самовывоза")) | I36: =IF(B36="","",N(E36)-N(F36)-G36-H36) | J36: =IF(B36="","",SUMIFS(Заказы!$I$4:$I$1003,Заказы!$E$4:$E$1003,B36,Заказы!$O$4:$O$1003,"Выполнен")) | K36: =IF(B36="","",SUMIFS(Заказы!$M$4:$M$1003,Заказы!$E$4:$E$1003,B36,Заказы!$O$4:$O$1003,"Выполнен")) | L36: =IF(B36="","",SUMIFS(Заказы!$I$4:$I$1003,Заказы!$E$4:$E$1003,B36,Заказы!$O$4:$O$1003,"Ожидает отправки")+SUMIFS(Заказы!$I$4:$I$1003,Заказы!$E$4:$E$1003,B36,Заказы!$O$4:$O$1003,"Отправлен (в пути)")+SUMIFS(Заказы!$I$4:$I$1003,Заказы!$E$4:$E$1003,B36,Заказы!$O$4:$O$1003,"Ожидает самовывоза")) | M36: =IF(OR(B36="",N(J36)=0),"",K36/J36)
A37: =IF(B37="","",ROW()-3) | G37: =IF(B37="","",SUMIFS(Заказы!$F$4:$F$1003,Заказы!$E$4:$E$1003,B37,Заказы!$O$4:$O$1003,"Выполнен")) | H37: =IF(B37="","",SUMIFS(Заказы!$F$4:$F$1003,Заказы!$E$4:$E$1003,B37,Заказы!$O$4:$O$1003,"Ожидает отправки")+SUMIFS(Заказы!$F$4:$F$1003,Заказы!$E$4:$E$1003,B37,Заказы!$O$4:$O$1003,"Отправлен (в пути)")+SUMIFS(Заказы!$F$4:$F$1003,Заказы!$E$4:$E$1003,B37,Заказы!$O$4:$O$1003,"Ожидает самовывоза")) | I37: =IF(B37="","",N(E37)-N(F37)-G37-H37) | J37: =IF(B37="","",SUMIFS(Заказы!$I$4:$I$1003,Заказы!$E$4:$E$1003,B37,Заказы!$O$4:$O$1003,"Выполнен")) | K37: =IF(B37="","",SUMIFS(Заказы!$M$4:$M$1003,Заказы!$E$4:$E$1003,B37,Заказы!$O$4:$O$1003,"Выполнен")) | L37: =IF(B37="","",SUMIFS(Заказы!$I$4:$I$1003,Заказы!$E$4:$E$1003,B37,Заказы!$O$4:$O$1003,"Ожидает отправки")+SUMIFS(Заказы!$I$4:$I$1003,Заказы!$E$4:$E$1003,B37,Заказы!$O$4:$O$1003,"Отправлен (в пути)")+SUMIFS(Заказы!$I$4:$I$1003,Заказы!$E$4:$E$1003,B37,Заказы!$O$4:$O$1003,"Ожидает самовывоза")) | M37: =IF(OR(B37="",N(J37)=0),"",K37/J37)
A38: =IF(B38="","",ROW()-3) | G38: =IF(B38="","",SUMIFS(Заказы!$F$4:$F$1003,Заказы!$E$4:$E$1003,B38,Заказы!$O$4:$O$1003,"Выполнен")) | H38: =IF(B38="","",SUMIFS(Заказы!$F$4:$F$1003,Заказы!$E$4:$E$1003,B38,Заказы!$O$4:$O$1003,"Ожидает отправки")+SUMIFS(Заказы!$F$4:$F$1003,Заказы!$E$4:$E$1003,B38,Заказы!$O$4:$O$1003,"Отправлен (в пути)")+SUMIFS(Заказы!$F$4:$F$1003,Заказы!$E$4:$E$1003,B38,Заказы!$O$4:$O$1003,"Ожидает самовывоза")) | I38: =IF(B38="","",N(E38)-N(F38)-G38-H38) | J38: =IF(B38="","",SUMIFS(Заказы!$I$4:$I$1003,Заказы!$E$4:$E$1003,B38,Заказы!$O$4:$O$1003,"Выполнен")) | K38: =IF(B38="","",SUMIFS(Заказы!$M$4:$M$1003,Заказы!$E$4:$E$1003,B38,Заказы!$O$4:$O$1003,"Выполнен")) | L38: =IF(B38="","",SUMIFS(Заказы!$I$4:$I$1003,Заказы!$E$4:$E$1003,B38,Заказы!$O$4:$O$1003,"Ожидает отправки")+SUMIFS(Заказы!$I$4:$I$1003,Заказы!$E$4:$E$1003,B38,Заказы!$O$4:$O$1003,"Отправлен (в пути)")+SUMIFS(Заказы!$I$4:$I$1003,Заказы!$E$4:$E$1003,B38,Заказы!$O$4:$O$1003,"Ожидает самовывоза")) | M38: =IF(OR(B38="",N(J38)=0),"",K38/J38)
A39: =IF(B39="","",ROW()-3) | G39: =IF(B39="","",SUMIFS(Заказы!$F$4:$F$1003,Заказы!$E$4:$E$1003,B39,Заказы!$O$4:$O$1003,"Выполнен")) | H39: =IF(B39="","",SUMIFS(Заказы!$F$4:$F$1003,Заказы!$E$4:$E$1003,B39,Заказы!$O$4:$O$1003,"Ожидает отправки")+SUMIFS(Заказы!$F$4:$F$1003,Заказы!$E$4:$E$1003,B39,Заказы!$O$4:$O$1003,"Отправлен (в пути)")+SUMIFS(Заказы!$F$4:$F$1003,Заказы!$E$4:$E$1003,B39,Заказы!$O$4:$O$1003,"Ожидает самовывоза")) | I39: =IF(B39="","",N(E39)-N(F39)-G39-H39) | J39: =IF(B39="","",SUMIFS(Заказы!$I$4:$I$1003,Заказы!$E$4:$E$1003,B39,Заказы!$O$4:$O$1003,"Выполнен")) | K39: =IF(B39="","",SUMIFS(Заказы!$M$4:$M$1003,Заказы!$E$4:$E$1003,B39,Заказы!$O$4:$O$1003,"Выполнен")) | L39: =IF(B39="","",SUMIFS(Заказы!$I$4:$I$1003,Заказы!$E$4:$E$1003,B39,Заказы!$O$4:$O$1003,"Ожидает отправки")+SUMIFS(Заказы!$I$4:$I$1003,Заказы!$E$4:$E$1003,B39,Заказы!$O$4:$O$1003,"Отправлен (в пути)")+SUMIFS(Заказы!$I$4:$I$1003,Заказы!$E$4:$E$1003,B39,Заказы!$O$4:$O$1003,"Ожидает самовывоза")) | M39: =IF(OR(B39="",N(J39)=0),"",K39/J39)
A40: =IF(B40="","",ROW()-3) | G40: =IF(B40="","",SUMIFS(Заказы!$F$4:$F$1003,Заказы!$E$4:$E$1003,B40,Заказы!$O$4:$O$1003,"Выполнен")) | H40: =IF(B40="","",SUMIFS(Заказы!$F$4:$F$1003,Заказы!$E$4:$E$1003,B40,Заказы!$O$4:$O$1003,"Ожидает отправки")+SUMIFS(Заказы!$F$4:$F$1003,Заказы!$E$4:$E$1003,B40,Заказы!$O$4:$O$1003,"Отправлен (в пути)")+SUMIFS(Заказы!$F$4:$F$1003,Заказы!$E$4:$E$1003,B40,Заказы!$O$4:$O$1003,"Ожидает самовывоза")) | I40: =IF(B40="","",N(E40)-N(F40)-G40-H40) | J40: =IF(B40="","",SUMIFS(Заказы!$I$4:$I$1003,Заказы!$E$4:$E$1003,B40,Заказы!$O$4:$O$1003,"Выполнен")) | K40: =IF(B40="","",SUMIFS(Заказы!$M$4:$M$1003,Заказы!$E$4:$E$1003,B40,Заказы!$O$4:$O$1003,"Выполнен")) | L40: =IF(B40="","",SUMIFS(Заказы!$I$4:$I$1003,Заказы!$E$4:$E$1003,B40,Заказы!$O$4:$O$1003,"Ожидает отправки")+SUMIFS(Заказы!$I$4:$I$1003,Заказы!$E$4:$E$1003,B40,Заказы!$O$4:$O$1003,"Отправлен (в пути)")+SUMIFS(Заказы!$I$4:$I$1003,Заказы!$E$4:$E$1003,B40,Заказы!$O$4:$O$1003,"Ожидает самовывоза")) | M40: =IF(OR(B40="",N(J40)=0),"",K40/J40)
...

Sheet Заказы
A1: ЗАКАЗЫ — один общий список
A2: Жёлтые колонки заполняете вы, серые считаются сами. Фильтр по «Статусу» — стрелка в заголовке.
A3: № | B3: Дата заказа | C3: Клиент | D3: Телефон | E3: Товар | F3: Кол-во | G3: Цена (прайс) | H3: Скидка, ₽ | I3: Сумма за товар | J3: Доставка, ₽ | K3: ИТОГО с доставкой | L3: Себестоимость | M3: Прибыль | N3: Получение | O3: Статус | P3: Оплата | Q3: Адрес / трек-номер | R3: Дата выдачи | S3: Комментарий
A4: =IF(E4="","",ROW()-3) -> 1 | B4: 46315 | C4: Пример: Магомед | D4: +7 900 000-00-01 | E4: Натурал коллаген | F4: 2 | G4: =IF(E4="","",IFERROR(INDEX(Товары!$D$4:$D$200,MATCH(E4,Товары!$B$4:$B$200,0)),0)) -> 5000 | H4: 500 | I4: =IF(OR(E4="",F4=""),"",F4*G4-N(H4)) -> 9500 | K4: =IF(AND(I4="",N(J4)=0),"",N(I4)+N(J4)) -> 9500 | L4: =IF(OR(E4="",F4=""),"",F4*IFERROR(INDEX(Товары!$C$4:$C$200,MATCH(E4,Товары!$B$4:$B$200,0)),0)) -> 7000 | M4: =IF(I4="","",I4-L4) -> 2500 | N4: Самовывоз | O4: Выполнен | P4: Оплачен | R4: 46315 | S4: ПРИМЕР — удалите строку
A5: =IF(E5="","",ROW()-3) -> 2 | B5: 46317 | C5: Пример: Аминат | D5: +7 900 000-00-02 | E5: Цинк | F5: 1 | G5: =IF(E5="","",IFERROR(INDEX(Товары!$D$4:$D$200,MATCH(E5,Товары!$B$4:$B$200,0)),0)) -> 1700 | I5: =IF(OR(E5="",F5=""),"",F5*G5-N(H5)) -> 1700 | J5: 400 | K5: =IF(AND(I5="",N(J5)=0),"",N(I5)+N(J5)) -> 2100 | L5: =IF(OR(E5="",F5=""),"",F5*IFERROR(INDEX(Товары!$C$4:$C$200,MATCH(E5,Товары!$B$4:$B$200,0)),0)) -> 1000 | M5: =IF(I5="","",I5-L5) -> 700 | N5: СДЭК | O5: Ожидает отправки | P5: Предоплата | Q5: СДЭК, Махачкала, ПВЗ ул. ... | S5: ПРИМЕР — удалите строку
A6: =IF(E6="","",ROW()-3) -> 3 | B6: 46318 | C6: Пример: Ислам | D6: +7 900 000-00-03 | E6: Reta 20mg | F6: 1 | G6: =IF(E6="","",IFERROR(INDEX(Товары!$D$4:$D$200,MATCH(E6,Товары!$B$4:$B$200,0)),0)) -> 12500 | H6: 1000 | I6: =IF(OR(E6="",F6=""),"",F6*G6-N(H6)) -> 11500 | J6: 300 | K6: =IF(AND(I6="",N(J6)=0),"",N(I6)+N(J6)) -> 11800 | L6: =IF(OR(E6="",F6=""),"",F6*IFERROR(INDEX(Товары!$C$4:$C$200,MATCH(E6,Товары!$B$4:$B$200,0)),0)) -> 7000 | M6: =IF(I6="","",I6-L6) -> 4500 | N6: Маршрутка | O6: Ожидает самовывоза | P6: Не оплачен | S6: ПРИМЕР — удалите строку
A7: =IF(E7="","",ROW()-3) | G7: =IF(E7="","",IFERROR(INDEX(Товары!$D$4:$D$200,MATCH(E7,Товары!$B$4:$B$200,0)),0)) | I7: =IF(OR(E7="",F7=""),"",F7*G7-N(H7)) | K7: =IF(AND(I7="",N(J7)=0),"",N(I7)+N(J7)) | L7: =IF(OR(E7="",F7=""),"",F7*IFERROR(INDEX(Товары!$C$4:$C$200,MATCH(E7,Товары!$B$4:$B$200,0)),0)) | M7: =IF(I7="","",I7-L7)
A8: =IF(E8="","",ROW()-3) | G8: =IF(E8="","",IFERROR(INDEX(Товары!$D$4:$D$200,MATCH(E8,Товары!$B$4:$B$200,0)),0)) | I8: =IF(OR(E8="",F8=""),"",F8*G8-N(H8)) | K8: =IF(AND(I8="",N(J8)=0),"",N(I8)+N(J8)) | L8: =IF(OR(E8="",F8=""),"",F8*IFERROR(INDEX(Товары!$C$4:$C$200,MATCH(E8,Товары!$B$4:$B$200,0)),0)) | M8: =IF(I8="","",I8-L8)
A9: =IF(E9="","",ROW()-3) | G9: =IF(E9="","",IFERROR(INDEX(Товары!$D$4:$D$200,MATCH(E9,Товары!$B$4:$B$200,0)),0)) | I9: =IF(OR(E9="",F9=""),"",F9*G9-N(H9)) | K9: =IF(AND(I9="",N(J9)=0),"",N(I9)+N(J9)) | L9: =IF(OR(E9="",F9=""),"",F9*IFERROR(INDEX(Товары!$C$4:$C$200,MATCH(E9,Товары!$B$4:$B$200,0)),0)) | M9: =IF(I9="","",I9-L9)
A10: =IF(E10="","",ROW()-3) | G10: =IF(E10="","",IFERROR(INDEX(Товары!$D$4:$D$200,MATCH(E10,Товары!$B$4:$B$200,0)),0)) | I10: =IF(OR(E10="",F10=""),"",F10*G10-N(H10)) | K10: =IF(AND(I10="",N(J10)=0),"",N(I10)+N(J10)) | L10: =IF(OR(E10="",F10=""),"",F10*IFERROR(INDEX(Товары!$C$4:$C$200,MATCH(E10,Товары!$B$4:$B$200,0)),0)) | M10: =IF(I10="","",I10-L10)
A11: =IF(E11="","",ROW()-3) | G11: =IF(E11="","",IFERROR(INDEX(Товары!$D$4:$D$200,MATCH(E11,Товары!$B$4:$B$200,0)),0)) | I11: =IF(OR(E11="",F11=""),"",F11*G11-N(H11)) | K11: =IF(AND(I11="",N(J11)=0),"",N(I11)+N(J11)) | L11: =IF(OR(E11="",F11=""),"",F11*IFERROR(INDEX(Товары!$C$4:$C$200,MATCH(E11,Товары!$B$4:$B$200,0)),0)) | M11: =IF(I11="","",I11-L11)
A12: =IF(E12="","",ROW()-3) | G12: =IF(E12="","",IFERROR(INDEX(Товары!$D$4:$D$200,MATCH(E12,Товары!$B$4:$B$200,0)),0)) | I12: =IF(OR(E12="",F12=""),"",F12*G12-N(H12)) | K12: =IF(AND(I12="",N(J12)=0),"",N(I12)+N(J12)) | L12: =IF(OR(E12="",F12=""),"",F12*IFERROR(INDEX(Товары!$C$4:$C$200,MATCH(E12,Товары!$B$4:$B$200,0)),0)) | M12: =IF(I12="","",I12-L12)
A13: =IF(E13="","",ROW()-3) | G13: =IF(E13="","",IFERROR(INDEX(Товары!$D$4:$D$200,MATCH(E13,Товары!$B$4:$B$200,0)),0)) | I13: =IF(OR(E13="",F13=""),"",F13*G13-N(H13)) | K13: =IF(AND(I13="",N(J13)=0),"",N(I13)+N(J13)) | L13: =IF(OR(E13="",F13=""),"",F13*IFERROR(INDEX(Товары!$C$4:$C$200,MATCH(E13,Товары!$B$4:$B$200,0)),0)) | M13: =IF(I13="","",I13-L13)
A14: =IF(E14="","",ROW()-3) | G14: =IF(E14="","",IFERROR(INDEX(Товары!$D$4:$D$200,MATCH(E14,Товары!$B$4:$B$200,0)),0)) | I14: =IF(OR(E14="",F14=""),"",F14*G14-N(H14)) | K14: =IF(AND(I14="",N(J14)=0),"",N(I14)+N(J14)) | L14: =IF(OR(E14="",F14=""),"",F14*IFERROR(INDEX(Товары!$C$4:$C$200,MATCH(E14,Товары!$B$4:$B$200,0)),0)) | M14: =IF(I14="","",I14-L14)
A15: =IF(E15="","",ROW()-3) | G15: =IF(E15="","",IFERROR(INDEX(Товары!$D$4:$D$200,MATCH(E15,Товары!$B$4:$B$200,0)),0)) | I15: =IF(OR(E15="",F15=""),"",F15*G15-N(H15)) | K15: =IF(AND(I15="",N(J15)=0),"",N(I15)+N(J15)) | L15: =IF(OR(E15="",F15=""),"",F15*IFERROR(INDEX(Товары!$C$4:$C$200,MATCH(E15,Товары!$B$4:$B$200,0)),0)) | M15: =IF(I15="","",I15-L15)
A16: =IF(E16="","",ROW()-3) | G16: =IF(E16="","",IFERROR(INDEX(Товары!$D$4:$D$200,MATCH(E16,Товары!$B$4:$B$200,0)),0)) | I16: =IF(OR(E16="",F16=""),"",F16*G16-N(H16)) | K16: =IF(AND(I16="",N(J16)=0),"",N(I16)+N(J16)) | L16: =IF(OR(E16="",F16=""),"",F16*IFERROR(INDEX(Товары!$C$4:$C$200,MATCH(E16,Товары!$B$4:$B$200,0)),0)) | M16: =IF(I16="","",I16-L16)
A17: =IF(E17="","",ROW()-3) | G17: =IF(E17="","",IFERROR(INDEX(Товары!$D$4:$D$200,MATCH(E17,Товары!$B$4:$B$200,0)),0)) | I17: =IF(OR(E17="",F17=""),"",F17*G17-N(H17)) | K17: =IF(AND(I17="",N(J17)=0),"",N(I17)+N(J17)) | L17: =IF(OR(E17="",F17=""),"",F17*IFERROR(INDEX(Товары!$C$4:$C$200,MATCH(E17,Товары!$B$4:$B$200,0)),0)) | M17: =IF(I17="","",I17-L17)
A18: =IF(E18="","",ROW()-3) | G18: =IF(E18="","",IFERROR(INDEX(Товары!$D$4:$D$200,MATCH(E18,Товары!$B$4:$B$200,0)),0)) | I18: =IF(OR(E18="",F18=""),"",F18*G18-N(H18)) | K18: =IF(AND(I18="",N(J18)=0),"",N(I18)+N(J18)) | L18: =IF(OR(E18="",F18=""),"",F18*IFERROR(INDEX(Товары!$C$4:$C$200,MATCH(E18,Товары!$B$4:$B$200,0)),0)) | M18: =IF(I18="","",I18-L18)
... A1003: =IF(E1003="","",ROW()-3) | G1003: =IF(E1003="","",IFERROR(INDEX(Товары!$D$4:$D$200,MATCH(E1003,Товары!$B$4:$B$200,0)),0)) | I1003: =IF(OR(E1003="",F1003=""),"",F1003*G1003-N(H1003)) | K1003: =IF(AND(I1003="",N(J1003)=0),"",N(I1003)+N(J1003)) | L1003: =IF(OR(E1003="",F1003=""),"",F1003*IFERROR(INDEX(Товары!$C$4:$C$200,MATCH(E1003,Товары!$B$4:$B$200,0)),0)) | M1003: =IF(I1003="","",I1003-L1003)

Sheet Как пользоваться
A1: КАК ПОЛЬЗОВАТЬСЯ
A3: 1. Новый заказ → лист «Заказы», первая пустая строка. Заполните жёлтые колонки: дата, клиент, телефон, товар (из списка), кол-во, скидка, доставка ₽, способ получения, статус, оплата.
A4: Цена, сумма за товар, ИТОГО с доставкой, себестоимость и прибыль посчитаются сами. Доставка в прибыль не входит — её платит клиент, она только добавляется к итогу.
A5: Способы получения: Самовывоз, СДЭК, Маршрутка, Курьер, Почта. Несколько товаров в одном заказе — доставку пишите только в первой строке заказа.
A6: 2. Статусы (меняйте по ходу дела — строка перекрашивается):
A7: • Ожидает отправки — заказ принят, ещё не отправлен (жёлтый)
A8: • Отправлен (в пути) — отправили, клиент ещё не получил (голубой)
A9: • Ожидает самовывоза — клиент ещё не забрал (оранжевый)
A10: • Выполнен — клиент получил товар, деньги у вас (зелёный). Только эти заказы идут в выручку и прибыль.
A11: • Отменён — не считается нигде, товар возвращается в остаток (серый, зачёркнут)
A12: 3. Чтобы увидеть только ожидающих — стрелка фильтра в заголовке «Статус» на листе «Заказы».
A13: 4. Если клиент берёт несколько разных товаров — каждый товар отдельной строкой, клиента и дату повторить.
... A20: «Продано ранее» на листе «Товары» взято из колонки КОЛ-ПРОД вашей кассы — чтобы остатки сразу были правильные. Если не нужно — очистите колонку.
